/home/guoj5/Documents/dinov2-main/dinov2/layers/swiglu_ffn.py:43: UserWarning: xFormers is available (SwiGLU)
  warnings.warn("xFormers is available (SwiGLU)")
/home/guoj5/Documents/dinov2-main/dinov2/layers/attention.py:27: UserWarning: xFormers is available (Attention)
  warnings.warn("xFormers is available (Attention)")
/home/guoj5/Documents/dinov2-main/dinov2/layers/block.py:33: UserWarning: xFormers is available (Block)
  warnings.warn("xFormers is available (Block)")
fatal: not a git repository (or any of the parent directories): .git
submitit ERROR (2024-03-19 21:28:28,169) - Submitted job triggered an exception
Traceback (most recent call last):
  File "/home/guoj5/anaconda3/envs/dinov2_env/lib/python3.9/site-packages/submitit/core/submission.py", line 69, in process_job
    raise error
  File "/home/guoj5/anaconda3/envs/dinov2_env/lib/python3.9/site-packages/submitit/core/submission.py", line 55, in process_job
    result = delayed.result()
  File "/home/guoj5/anaconda3/envs/dinov2_env/lib/python3.9/site-packages/submitit/core/utils.py", line 133, in result
    self._result = self.function(*self.args, **self.kwargs)
  File "/home/guoj5/Documents/dinov2-main/dinov2/run/eval/linear.py", line 26, in __call__
    linear_main(self.args)
  File "/home/guoj5/Documents/dinov2-main/dinov2/eval/linear.py", line 597, in main
    run_eval_linear(
  File "/home/guoj5/Documents/dinov2-main/dinov2/eval/linear.py", line 495, in run_eval_linear
    train_dataset = make_dataset(
  File "/home/guoj5/Documents/dinov2-main/dinov2/data/loaders.py", line 89, in make_dataset
    logger.info(f"# of dataset samples: {len(dataset):,d}")
  File "/home/guoj5/Documents/dinov2-main/dinov2/data/datasets/image_net.py", line 167, in __len__
    entries = self._get_entries()
  File "/home/guoj5/Documents/dinov2-main/dinov2/data/datasets/image_net.py", line 107, in _get_entries
    self._entries = self._load_extra(self._entries_path)
  File "/home/guoj5/Documents/dinov2-main/dinov2/data/datasets/image_net.py", line 86, in _load_extra
    return np.load(extra_full_path, mmap_mode="r")
  File "/home/guoj5/anaconda3/envs/dinov2_env/lib/python3.9/site-packages/numpy/lib/npyio.py", line 405, in load
    fid = stack.enter_context(open(os_fspath(file), "rb"))
FileNotFoundError: [Errno 2] No such file or directory: '/media/guoj5/T7 Shield/datasets/imagenet1k_meta/entries-TRAIN.npy'
Error in sys.excepthook:
Traceback (most recent call last):
  File "/home/guoj5/Desktop/pycharm-2023.3.4/plugins/python/helpers/pydev/_pydevd_bundle/pydevd_constants.py", line 58, in dummy_excepthook
    def dummy_excepthook(exctype, value, traceback):
KeyboardInterrupt

Original exception was:
Traceback (most recent call last):
  File "/home/guoj5/Desktop/pycharm-2023.3.4/plugins/python/helpers/pydev/pydevd.py", line 2235, in <module>
    main()
  File "/home/guoj5/Desktop/pycharm-2023.3.4/plugins/python/helpers/pydev/pydevd.py", line 2217, in main
    globals = debugger.run(setup['file'], None, None, is_module)
  File "/home/guoj5/Desktop/pycharm-2023.3.4/plugins/python/helpers/pydev/pydevd.py", line 1527, in run
    return self._exec(is_module, entry_point_fn, module_name, file, globals, locals)
  File "/home/guoj5/Desktop/pycharm-2023.3.4/plugins/python/helpers/pydev/pydevd.py", line 1551, in _exec
    runpy._run_module_as_main(module_name, alter_argv=False)
  File "/home/guoj5/Desktop/pycharm-2023.3.4/plugins/python/helpers/pydev/_pydevd_bundle/pydevd_trace_dispatch_regular.py", line 232, in trace_unhandled_exceptions
    stop_on_unhandled_exception(py_db, t, additional_info, arg)
  File "/home/guoj5/Desktop/pycharm-2023.3.4/plugins/python/helpers/pydev/_pydevd_bundle/pydevd_breakpoints.py", line 174, in stop_on_unhandled_exception
    py_db.stop_on_unhandled_exception(thread, frame, frames_byid, arg)
  File "/home/guoj5/Desktop/pycharm-2023.3.4/plugins/python/helpers/pydev/pydevd.py", line 1300, in stop_on_unhandled_exception
    raise e
  File "/home/guoj5/Desktop/pycharm-2023.3.4/plugins/python/helpers/pydev/pydevd.py", line 1298, in stop_on_unhandled_exception
    self.do_wait_suspend(thread, frame, 'exception', arg, is_unhandled_exception=True)
  File "/home/guoj5/Desktop/pycharm-2023.3.4/plugins/python/helpers/pydev/pydevd.py", line 1184, in do_wait_suspend
    self._do_wait_suspend(thread, frame, event, arg, suspend_type, from_this_thread)
  File "/home/guoj5/Desktop/pycharm-2023.3.4/plugins/python/helpers/pydev/pydevd.py", line 1199, in _do_wait_suspend
    time.sleep(0.01)
KeyboardInterrupt
